Workbook

Sheet Inputs
A1: IDBI BANK – FINANCIAL MODEL INPUTS
A3: LEGEND
A4: Blue Font = Hardcoded Input | B4: Black Font = Formula / Calculation
A6: CURRENT VALUATION (April 2026)
A7: Stock Price (CMP) – ₹ | B7: 69.55
A8: Market Cap – ₹ Crore | B8: 74782.96
A9: Shares Outstanding – Billion | B9: 10.75
A10: 52-Week High – ₹ | B10: 118.38
A11: 52-Week Low – ₹ | B11: 61.01
A12: P/E Ratio | B12: 8.05
A13: P/B Ratio | B13: 1.12
A14: EPS (TTM) – ₹ | B14: 8.64
A15: Book Value per Share – ₹ | B15: 65
A17: FY 2024-25 INCOME STATEMENT ACTUALS – ₹ Millions
A18: Line Item | B18: FY 2024-25 | C18: FY 2023-24
A19: Interest Income | B19: 289171 | C19: 264571
A20: Other Income | B20: 60000 | C20: 55000
A21: Total Income | B21: 349171 | C21: 319571
A22: Interest Expenses | B22: 142566 | C22: 132059
A23: Net Interest Income | B23: 146605 | C23: 142187
A24: Operating Expenses | B24: 86190 | C24: 83679
A25: Provisions & Contingencies | B25: 31500 | C25: 33000
A26: Pre-Tax Profit | B26: 89915 | C26: 68508
A27: Tax | B27: 13608 | C27: 10000
A28: Net Profit After Tax | B28: 76307 | C28: 57850
A30: FY 2024-25 BALANCE SHEET – ₹ Crore
A31: Line Item | B31: FY 2024-25 | C31: FY 2023-24
A32: Total Assets | B32: 412962 | C32: 364755
A33: Cash & Equivalents | B33: 35000 | C33: 28000
A34: Investments | B34: 120000 | C34: 110000
A35: Advances | B35: 218212 | C35: 188440
A36: Other Assets | B36: 39750 | C36: 38315
A37: Total Deposits | B37: 309975 | C37: 277295
A38: Borrowings | B38: 40000 | C38: 38000
A39: Other Liabilities | B39: 25800 | C39: 23000
A40: Total Equity | B40: 37187 | C40: 26460
A41: Paid-up Capital | B41: 10750 | C41: 10750
A42: Reserves & Surplus | B42: 26437 | C42: 15710
A44: KEY RATIOS (FY 2024-25)
A45: Return on Equity (ROE) % | B45: 0.2015
...

Sheet 3-Statements Model
A1: IDBI BANK – 3-STATEMENTS MODEL
A2: Line Item | B2: FY 2024-25 | C2: FY 2025-26 | D2: FY 2026-27 | E2: FY 2027-28 | F2: FY 2028-29
A3: INCOME STATEMENT (₹ Millions)
A4: Interest Income | B4: =Inputs!B19 | C4: =IF(Inputs!B70="Bull",B4*(1+Inputs!C56),IF(Inputs!B70="Bear",B4*(1+Inputs!D56),B4*(1+Inputs!B56))) | D4: =IF(Inputs!B70="Bull",C4*(1+Inputs!C56),IF(Inputs!B70="Bear",C4*(1+Inputs!D56),C4*(1+Inputs!B56))) | E4: =IF(Inputs!B70="Bull",D4*(1+Inputs!C56),IF(Inputs!B70="Bear",D4*(1+Inputs!D56),D4*(1+Inputs!B56))) | F4: =IF(Inputs!B70="Bull",E4*(1+Inputs!C56),IF(Inputs!B70="Bear",E4*(1+Inputs!D56),E4*(1+Inputs!B56)))
A5: Other Income | B5: =Inputs!B20 | C5: =IF(Inputs!B70="Bull",B5*(1+Inputs!C58),IF(Inputs!B70="Bear",B5*(1+Inputs!D58),B5*(1+Inputs!B58))) | D5: =IF(Inputs!B70="Bull",C5*(1+Inputs!C58),IF(Inputs!B70="Bear",C5*(1+Inputs!D58),C5*(1+Inputs!B58))) | E5: =IF(Inputs!B70="Bull",D5*(1+Inputs!C58),IF(Inputs!B70="Bear",D5*(1+Inputs!D58),D5*(1+Inputs!B58))) | F5: =IF(Inputs!B70="Bull",E5*(1+Inputs!C58),IF(Inputs!B70="Bear",E5*(1+Inputs!D58),E5*(1+Inputs!B58)))
A6: Total Income | B6: =B4+B5 | C6: =C4+C5 | D6: =D4+D5 | E6: =E4+E5 | F6: =F4+F5
A7: Interest Expenses | B7: =Inputs!B22 | C7: =IF(Inputs!B70="Bull",B7*(1+Inputs!C60),IF(Inputs!B70="Bear",B7*(1+Inputs!D60),B7*(1+Inputs!B60))) | D7: =IF(Inputs!B70="Bull",C7*(1+Inputs!C60),IF(Inputs!B70="Bear",C7*(1+Inputs!D60),C7*(1+Inputs!B60))) | E7: =IF(Inputs!B70="Bull",D7*(1+Inputs!C60),IF(Inputs!B70="Bear",D7*(1+Inputs!D60),D7*(1+Inputs!B60))) | F7: =IF(Inputs!B70="Bull",E7*(1+Inputs!C60),IF(Inputs!B70="Bear",E7*(1+Inputs!D60),E7*(1+Inputs!B60)))
A8: Net Interest Income | B8: =B6-B7 | C8: =C6-C7 | D8: =D6-D7 | E8: =E6-E7 | F8: =F6-F7
A9: Operating Expenses | B9: =IF(Inputs!B70="Bull",B6*Inputs!C59,IF(Inputs!B70="Bear",B6*Inputs!D59,B6*Inputs!B59)) | C9: =IF(Inputs!B70="Bull",C6*Inputs!C59,IF(Inputs!B70="Bear",C6*Inputs!D59,C6*Inputs!B59)) | D9: =IF(Inputs!B70="Bull",D6*Inputs!C59,IF(Inputs!B70="Bear",D6*Inputs!D59,D6*Inputs!B59)) | E9: =IF(Inputs!B70="Bull",E6*Inputs!C59,IF(Inputs!B70="Bear",E6*Inputs!D59,E6*Inputs!B59)) | F9: =IF(Inputs!B70="Bull",F6*Inputs!C59,IF(Inputs!B70="Bear",F6*Inputs!D59,F6*Inputs!B59))
A10: Provisions & Contingencies | B10: =IF(Inputs!B70="Bull",B8*Inputs!C63,IF(Inputs!B70="Bear",B8*Inputs!D63,B8*Inputs!B63)) | C10: =IF(Inputs!B70="Bull",C8*Inputs!C63,IF(Inputs!B70="Bear",C8*Inputs!D63,C8*Inputs!B63)) | D10: =IF(Inputs!B70="Bull",D8*Inputs!C63,IF(Inputs!B70="Bear",D8*Inputs!D63,D8*Inputs!B63)) | E10: =IF(Inputs!B70="Bull",E8*Inputs!C63,IF(Inputs!B70="Bear",E8*Inputs!D63,E8*Inputs!B63)) | F10: =IF(Inputs!B70="Bull",F8*Inputs!C63,IF(Inputs!B70="Bear",F8*Inputs!D63,F8*Inputs!B63))
A11: Pre-Tax Profit | B11: =B8-B9-B10 | C11: =C8-C9-C10 | D11: =D8-D9-D10 | E11: =E8-E9-E10 | F11: =F8-F9-F10
A12: Tax (30%) | B12: =IF(Inputs!B70="Bull",B11*Inputs!C64,IF(Inputs!B70="Bear",B11*Inputs!D64,B11*Inputs!B64)) | C12: =IF(Inputs!B70="Bull",C11*Inputs!C64,IF(Inputs!B70="Bear",C11*Inputs!D64,C11*Inputs!B64)) | D12: =IF(Inputs!B70="Bull",D11*Inputs!C64,IF(Inputs!B70="Bear",D11*Inputs!D64,D11*Inputs!B64)) | E12: =IF(Inputs!B70="Bull",E11*Inputs!C64,IF(Inputs!B70="Bear",E11*Inputs!D64,E11*Inputs!B64)) | F12: =IF(Inputs!B70="Bull",F11*Inputs!C64,IF(Inputs!B70="Bear",F11*Inputs!D64,F11*Inputs!B64))
A13: Net Profit After Tax (NPAT) | B13: =B11-B12 | C13: =C11-C12 | D13: =D11-D12 | E13: =E11-E12 | F13: =F11-F12
A15: KEY RATIOS
A16: Ratio | B16: FY 2024-25 | C16: FY 2025-26 | D16: FY 2026-27 | E16: FY 2027-28 | F16: FY 2028-29
A17: Net Profit Margin % | B17: =IF(B6=0,0,B13/B6) | C17: =IF(C6=0,0,C13/C6) | D17: =IF(D6=0,0,D13/D6) | E17: =IF(E6=0,0,E13/E6) | F17: =IF(F6=0,0,F13/F6)
A18: Cost to Income Ratio % | B18: =IF(B6=0,0,B9/B6) | C18: =IF(C6=0,0,C9/C6) | D18: =IF(D6=0,0,D9/D6) | E18: =IF(E6=0,0,E9/E6) | F18: =IF(F6=0,0,F9/F6)
A20: BALANCE SHEET (₹ Crore)
A21: Line Item | B21: FY 2024-25 | C21: FY 2025-26 | D21: FY 2026-27 | E21: FY 2027-28 | F21: FY 2028-29
A22: ASSETS
A23: Advances | B23: =Inputs!B35 | C23: =IF(Inputs!B70="Bull",B23*(1+Inputs!C61),IF(Inputs!B70="Bear",B23*(1+Inputs!D61),B23*(1+Inputs!B61))) | D23: =IF(Inputs!B70="Bull",C23*(1+Inputs!C61),IF(Inputs!B70="Bear",C23*(1+Inputs!D61),C23*(1+Inputs!B61))) | E23: =IF(Inputs!B70="Bull",D23*(1+Inputs!C61),IF(Inputs!B70="Bear",D23*(1+Inputs!D61),D23*(1+Inputs!B61))) | F23: =IF(Inputs!B70="Bull",E23*(1+Inputs!C61),IF(Inputs!B70="Bear",E23*(1+Inputs!D61),E23*(1+Inputs!B61)))
A24: Investments | B24: =Inputs!B34 | C24: =IF(Inputs!B70="Bull",B24*(1+0.65*Inputs!C61),IF(Inputs!B70="Bear",B24*(1+0.65*Inputs!D61),B24*(1+0.65*Inputs!B61))) | D24: =IF(Inputs!B70="Bull",C24*(1+0.65*Inputs!C61),IF(Inputs!B70="Bear",C24*(1+0.65*Inputs!D61),C24*(1+0.65*Inputs!B61))) | E24: =IF(Inputs!B70="Bull",D24*(1+0.65*Inputs!C61),IF(Inputs!B70="Bear",D24*(1+0.65*Inputs!D61),D24*(1+0.65*Inputs!B61))) | F24: =IF(Inputs!B70="Bull",E24*(1+0.65*Inputs!C61),IF(Inputs!B70="Bear",E24*(1+0.65*Inputs!D61),E24*(1+0.65*Inputs!B61)))
A25: Cash & Equivalents | B25: =Inputs!B33 | C25: =B25*1.05 | D25: =C25*1.05 | E25: =D25*1.05 | F25: =E25*1.05
A26: Other Assets | B26: =B23*0.18 | C26: =C23*0.18 | D26: =D23*0.18 | E26: =E23*0.18 | F26: =F23*0.18
A27: TOTAL ASSETS | B27: =B23+B24+B25+B26 | C27: =C23+C24+C25+C26 | D27: =D23+D24+D25+D26 | E27: =E23+E24+E25+E26 | F27: =F23+F24+F25+F26
A28: LIABILITIES
A29: Total Deposits | B29: =Inputs!B37 | C29: =IF(Inputs!B70="Bull",B29*(1+Inputs!C62),IF(Inputs!B70="Bear",B29*(1+Inputs!D62),B29*(1+Inputs!B62))) | D29: =IF(Inputs!B70="Bull",C29*(1+Inputs!C62),IF(Inputs!B70="Bear",C29*(1+Inputs!D62),C29*(1+Inputs!B62))) | E29: =IF(Inputs!B70="Bull",D29*(1+Inputs!C62),IF(Inputs!B70="Bear",D29*(1+Inputs!D62),D29*(1+Inputs!B62))) | F29: =IF(Inputs!B70="Bull",E29*(1+Inputs!C62),IF(Inputs!B70="Bear",E29*(1+Inputs!D62),E29*(1+Inputs!B62)))
A30: Borrowings | B30: =Inputs!B38 | C30: =B30*1.05 | D30: =C30*1.05 | E30: =D30*1.05 | F30: =E30*1.05
A31: Other Liabilities | B31: =B27*0.06 | C31: =C27*0.06 | D31: =D27*0.06 | E31: =E27*0.06 | F31: =F27*0.06
A32: Total Liabilities (excl. Equity) | B32: =B29+B30+B31 | C32: =C29+C30+C31 | D32: =D29+D30+D31 | E32: =E29+E30+E31 | F32: =F29+F30+F31
A33: EQUITY
A34: Paid-up Capital | B34: =Inputs!B41 | C34: =Inputs!B41 | D34: =Inputs!B41 | E34: =Inputs!B41 | F34: =Inputs!B41
A35: Reserves & Surplus | B35: =Inputs!B42 | C35: =B35+IF(Inputs!B70="Bull",(C13/10)*(1-Inputs!C65),IF(Inputs!B70="Bear",(C13/10)*(1-Inputs!D65),(C13/10)*(1-Inputs!B65))) | D35: =C35+IF(Inputs!B70="Bull",(D13/10)*(1-Inputs!C65),IF(Inputs!B70="Bear",(D13/10)*(1-Inputs!D65),(D13/10)*(1-Inputs!B65))) | E35: =D35+IF(Inputs!B70="Bull",(E13/10)*(1-Inputs!C65),IF(Inputs!B70="Bear",(E13/10)*(1-Inputs!D65),(E13/10)*(1-Inputs!B65))) | F35: =E35+IF(Inputs!B70="Bull",(F13/10)*(1-Inputs!C65),IF(Inputs!B70="Bear",(F13/10)*(1-Inputs!D65),(F13/10)*(1-Inputs!B65)))
A36: Total Equity | B36: =B34+B35 | C36: =C34+C35 | D36: =D34+D35 | E36: =E34+E35 | F36: =F34+F35
A37: Total Liabilities + Equity (balance check) | B37: =B32+B36 | C37: =C32+C36 | D37: =D32+D36 | E37: =E32+E36 | F37: =F32+F36
A39: CASH FLOW STATEMENT (₹ Millions)
A40: Line Item | B40: FY 2024-25 | C40: FY 2025-26 | D40: FY 2026-27 | E40: FY 2027-28 | F40: FY 2028-29
A41: Net Profit After Tax | B41: =B13 | C41: =C13 | D41: =D13 | E41: =E13 | F41: =F13
A42: Add: Provisions & Contingencies | B42: =B10 | C42: =C10 | D42: =D10 | E42: =E10 | F42: =F10
A43: Add: Depreciation (% of total assets) | B43: =B27*10*Inputs!B66 | C43: =C27*10*Inputs!B66 | D43: =D27*10*Inputs!B66 | E43: =E27*10*Inputs!B66 | F43: =F27*10*Inputs!B66
...

Sheet DCF Valuation
A1: IDBI BANK – DCF VALUATION
A2: Component | B2: FY 2024-25 | C2: FY 2025-26 | D2: FY 2026-27 | E2: FY 2027-28 | F2: FY 2028-29
A3: FREE CASH FLOW TO FIRM (FCFF) – ₹ Millions
A4: Net Profit After Tax | B4: ='3-Statements Model'!B13 | C4: ='3-Statements Model'!C13 | D4: ='3-Statements Model'!D13 | E4: ='3-Statements Model'!E13 | F4: ='3-Statements Model'!F13
A5: Add: Interest Expense × (1 – Tax Rate) | B5: ='3-Statements Model'!B7*(1-Inputs!B64) | C5: ='3-Statements Model'!C7*(1-Inputs!B64) | D5: ='3-Statements Model'!D7*(1-Inputs!B64) | E5: ='3-Statements Model'!E7*(1-Inputs!B64) | F5: ='3-Statements Model'!F7*(1-Inputs!B64)
A6: Less: Change in Working Capital (net advances – deposits) | B6: =0 | C6: =(-('3-Statements Model'!C23-'3-Statements Model'!B23)+'3-Statements Model'!C29-'3-Statements Model'!B29)*10 | D6: =(-('3-Statements Model'!D23-'3-Statements Model'!C23)+'3-Statements Model'!D29-'3-Statements Model'!C29)*10 | E6: =(-('3-Statements Model'!E23-'3-Statements Model'!D23)+'3-Statements Model'!E29-'3-Statements Model'!D29)*10 | F6: =(-('3-Statements Model'!F23-'3-Statements Model'!E23)+'3-Statements Model'!F29-'3-Statements Model'!E29)*10
A7: Less: Capital Expenditure | B7: ='3-Statements Model'!B47 | C7: ='3-Statements Model'!C47 | D7: ='3-Statements Model'!D47 | E7: ='3-Statements Model'!E47 | F7: ='3-Statements Model'!F47
A8: FCFF (Net Profit + Interest×(1-t) + ΔWC + CapEx) | B8: =B4+B5+B6+B7 | C8: =C4+C5+C6+C7 | D8: =D4+D5+D6+D7 | E8: =E4+E5+E6+E7 | F8: =F4+F5+F6+F7
A10: WACC & DISCOUNT RATE
A11: WACC % (from Inputs) | B11: =Inputs!B83
A12: Terminal Growth Rate (g) % (from Inputs) | B12: =Inputs!B86
A13: Terminal Value (Year-5 FCFF × (1+g) / (WACC-g)) | B13: =F8*(1+B12)/(B11-B12)
A15: PRESENT VALUE OF CASH FLOWS
A16: Period | B16: Year 1 | C16: Year 2 | D16: Year 3 | E16: Year 4 | F16: Year 5
A17: FCFF (₹ Mn) | B17: =B8 | C17: =C8 | D17: =D8 | E17: =E8 | F17: =F8
A18: Discount Factor [1/(1+WACC)^n] | B18: =1/(1+B11)^1 | C18: =1/(1+B11)^2 | D18: =1/(1+B11)^3 | E18: =1/(1+B11)^4 | F18: =1/(1+B11)^5
A19: PV of FCFF (₹ Mn) | B19: =B18*B17 | C19: =C18*C17 | D19: =D18*D17 | E19: =E18*E17 | F19: =F18*F17
A21: ENTERPRISE VALUE → EQUITY VALUE → IMPLIED PRICE
A22: Sum of PV of FCFFs (₹ Mn) | B22: =SUM(B19:F19)
A23: PV of Terminal Value (₹ Mn) | B23: =B13/(1+B11)^5
A24: Enterprise Value (₹ Mn) | B24: =B22+B23
A25: Less: Net Debt (Borrowings – Cash, ₹ Mn) | B25: =(Inputs!B38-Inputs!B33)*10
A26: Equity Value (₹ Mn) | B26: =B24-B25
A27: Shares Outstanding (Millions) | B27: =Inputs!B9*1000
A28: Implied Share Price (₹) | B28: =B26/B27
A29: Current Market Price (₹) | B29: =Inputs!B7
A30: Upside / Downside % | B30: =(B28-B29)/B29

Sheet Trading Comps
A1: IDBI BANK – TRADING COMPARABLES ANALYSIS
A2: Bank | B2: Market Cap (₹ Cr) | C2: Stock Price (₹) | D2: Shares (Cr) | E2: Net Profit (₹ Cr) | F2: NII / Rev. (₹ Cr) | G2: BV / Share (₹) | H2: EV/EBITDA | I2: EV/Rev. | J2: P/E | K2: P/B | L2: EV (₹ Cr)
A3: HDFC Bank | B3: =Inputs!B90 | C3: =Inputs!C90 | D3: =Inputs!D90 | E3: =Inputs!E90 | F3: =Inputs!F90 | G3: =Inputs!G90 | H3: =IF(E3=0,0,L3/(E3*1.3)) | I3: =IF(F3=0,0,L3/F3) | J3: =IF(E3=0,0,C3*D3/E3) | K3: =IF(G3=0,0,C3/G3) | L3: =B3*1.15
A4: ICICI Bank | B4: =Inputs!B91 | C4: =Inputs!C91 | D4: =Inputs!D91 | E4: =Inputs!E91 | F4: =Inputs!F91 | G4: =Inputs!G91 | H4: =IF(E4=0,0,L4/(E4*1.3)) | I4: =IF(F4=0,0,L4/F4) | J4: =IF(E4=0,0,C4*D4/E4) | K4: =IF(G4=0,0,C4/G4) | L4: =B4*1.15
A5: Axis Bank | B5: =Inputs!B92 | C5: =Inputs!C92 | D5: =Inputs!D92 | E5: =Inputs!E92 | F5: =Inputs!F92 | G5: =Inputs!G92 | H5: =IF(E5=0,0,L5/(E5*1.3)) | I5: =IF(F5=0,0,L5/F5) | J5: =IF(E5=0,0,C5*D5/E5) | K5: =IF(G5=0,0,C5/G5) | L5: =B5*1.15
A6: SBI | B6: =Inputs!B93 | C6: =Inputs!C93 | D6: =Inputs!D93 | E6: =Inputs!E93 | F6: =Inputs!F93 | G6: =Inputs!G93 | H6: =IF(E6=0,0,L6/(E6*1.3)) | I6: =IF(F6=0,0,L6/F6) | J6: =IF(E6=0,0,C6*D6/E6) | K6: =IF(G6=0,0,C6/G6) | L6: =B6*1.15
A7: Kotak Mahindra | B7: =Inputs!B94 | C7: =Inputs!C94 | D7: =Inputs!D94 | E7: =Inputs!E94 | F7: =Inputs!F94 | G7: =Inputs!G94 | H7: =IF(E7=0,0,L7/(E7*1.3)) | I7: =IF(F7=0,0,L7/F7) | J7: =IF(E7=0,0,C7*D7/E7) | K7: =IF(G7=0,0,C7/G7) | L7: =B7*1.15
A9: Median | H9: =MEDIAN(H3:H7) | I9: =MEDIAN(I3:I7) | J9: =MEDIAN(J3:J7) | K9: =MEDIAN(K3:K7)
A10: Min | H10: =MIN(H3:H7) | I10: =MIN(I3:I7) | J10: =MIN(J3:J7) | K10: =MIN(K3:K7)
A11: Max | H11: =MAX(H3:H7) | I11: =MAX(I3:I7) | J11: =MAX(J3:J7) | K11: =MAX(K3:K7)
A13: IDBI BANK – IMPLIED VALUATION (based on Peer Medians)
A14: Metric | B14: Median Multiple | C14: IDBI Metric (₹ Cr) | D14: Implied MC (₹ Cr) | E14: Implied Price (₹) | F14: CMP (₹) | G14: Upside %
A15: EV/EBITDA | B15: =H9 | C15: =Inputs!B28/10*1.3 | D15: =B15*C15/1.15 | E15: =D15*10/Inputs!B9 | F15: =Inputs!B7 | G15: =IF(F15=0,0,(E15-F15)/F15)
A16: EV/Revenue | B16: =I9 | C16: =Inputs!B23/10 | D16: =B16*C16/1.15 | E16: =D16*10/Inputs!B9 | F16: =Inputs!B7 | G16: =IF(F16=0,0,(E16-F16)/F16)
A17: P/E Ratio | B17: =J9 | C17: =Inputs!B14 | D17: =B17*C17*Inputs!B9*100 | E17: =B17*C17 | F17: =Inputs!B7 | G17: =IF(F17=0,0,(E17-F17)/F17)
A18: P/B Ratio | B18: =K9 | C18: =Inputs!B15 | D18: =B18*C18*Inputs!B9*100 | E18: =B18*C18 | F18: =Inputs!B7 | G18: =IF(F18=0,0,(E18-F18)/F18)

Sheet Scenario Analysis
A1: IDBI BANK – SCENARIO ANALYSIS
A2: SCENARIO SELECTOR (driven by Inputs sheet)
A3: Active Scenario: | B3: =Inputs!B70
A5: KEY ASSUMPTIONS BY SCENARIO
A6: Assumption | B6: Base Case | C6: Bull Case | D6: Bear Case
A7: Interest Income Growth % | B7: =Inputs!B56 | C7: =Inputs!C56 | D7: =Inputs!D56
A8: NII Growth % | B8: =Inputs!B57 | C8: =Inputs!C57 | D8: =Inputs!D57
A9: Cost to Income Ratio % | B9: =Inputs!B59 | C9: =Inputs!C59 | D9: =Inputs!D59
A10: Advance Growth % | B10: =Inputs!B61 | C10: =Inputs!C61 | D10: =Inputs!D61
A11: Deposit Growth % | B11: =Inputs!B62 | C11: =Inputs!C62 | D11: =Inputs!D62
A12: Provision Coverage % | B12: =Inputs!B63 | C12: =Inputs!C63 | D12: =Inputs!D63
A13: Tax Rate % | B13: =Inputs!B64 | C13: =Inputs!C64 | D13: =Inputs!D64
A15: P&L RESULTS – FY 2028-29 PROJECTIONS (₹ Millions)
A16: Metric | B16: Base Case | C16: Bull Case | D16: Bear Case
A17: Interest Income (₹ Mn) | B17: =Inputs!B19*(1+Inputs!B56)^4 | C17: =Inputs!B19*(1+Inputs!C56)^4 | D17: =Inputs!B19*(1+Inputs!D56)^4
A18: Net Interest Income (₹ Mn) | B18: =Inputs!B23*(1+Inputs!B57)^4 | C18: =Inputs!B23*(1+Inputs!C57)^4 | D18: =Inputs!B23*(1+Inputs!D57)^4
A19: Operating Expenses (₹ Mn) | B19: =Inputs!B19*(1+Inputs!B56)^4*Inputs!B59 | C19: =Inputs!B19*(1+Inputs!C56)^4*Inputs!C59 | D19: =Inputs!B19*(1+Inputs!D56)^4*Inputs!D59
A20: Provisions (₹ Mn) | B20: =B18*Inputs!B63 | C20: =C18*Inputs!C63 | D20: =D18*Inputs!D63
A21: Net Profit After Tax (₹ Mn) | B21: =(B18-Inputs!B19*(1+Inputs!B56)^4*Inputs!B59-B20)*(1-Inputs!B64) | C21: =(C18-Inputs!B19*(1+Inputs!C56)^4*Inputs!C59-C20)*(1-Inputs!C64) | D21: =(D18-Inputs!B19*(1+Inputs!D56)^4*Inputs!D59-D20)*(1-Inputs!D64)
A23: VALUATION SUMMARY BY SCENARIO
A24: Metric | B24: Base Case | C24: Bull Case | D24: Bear Case
A25: Terminal FCFF (NPAT FY28-29 × (1+g), ₹ Mn) | B25: =B21*(1+Inputs!B56) | C25: =C21*(1+Inputs!C56) | D25: =D21*(1+Inputs!D56)
A26: WACC (%) | B26: ='DCF Valuation'!B11 | C26: ='DCF Valuation'!B11 | D26: ='DCF Valuation'!B11
A27: Implied Share Price (₹) | B27: =(B25*(1+'DCF Valuation'!B12)/(MAX('DCF Valuation'!B11-'DCF Valuation'!B12,0.001)))/'DCF Valuation'!B27 | C27: =(C25*(1+'DCF Valuation'!B12)/(MAX('DCF Valuation'!B11-'DCF Valuation'!B12,0.001)))/'DCF Valuation'!B27 | D27: =(D25*(1+'DCF Valuation'!B12)/(MAX('DCF Valuation'!B11-'DCF Valuation'!B12,0.001)))/'DCF Valuation'!B27
A28: Current Market Price (₹) | B28: =Inputs!B7 | C28: =Inputs!B7 | D28: =Inputs!B7
A29: Upside / Downside (%) | B29: =(B27-Inputs!B7)/Inputs!B7 | C29: =(C27-Inputs!B7)/Inputs!B7 | D29: =(D27-Inputs!B7)/Inputs!B7

Sheet Sensitivity Analysis
A1: SENSITIVITY ANALYSIS – Implied Share Price (₹)
A2: 2-Way Table: WACC (columns, %) vs Terminal Growth Rate (rows, %)
A3: TGR \ WACC | B3: 0.08 | C3: 0.09 | D3: 0.1 | E3: 0.11 | F3: 0.12 | G3: 0.13 | H3: 0.14
A4: 0.02 | B4: =('DCF Valuation'!B8/(1+0.08)^1+'DCF Valuation'!C8/(1+0.08)^2+'DCF Valuation'!D8/(1+0.08)^3+'DCF Valuation'!E8/(1+0.08)^4+'DCF Valuation'!F8/(1+0.08)^5+'DCF Valuation'!F8*(1+0.02)/(MAX(0.08-0.02,0.0001))/(1+0.08)^5)/'DCF Valuation'!B27 | C4: =('DCF Valuation'!B8/(1+0.09)^1+'DCF Valuation'!C8/(1+0.09)^2+'DCF Valuation'!D8/(1+0.09)^3+'DCF Valuation'!E8/(1+0.09)^4+'DCF Valuation'!F8/(1+0.09)^5+'DCF Valuation'!F8*(1+0.02)/(MAX(0.09-0.02,0.0001))/(1+0.09)^5)/'DCF Valuation'!B27 | D4: =('DCF Valuation'!B8/(1+0.1)^1+'DCF Valuation'!C8/(1+0.1)^2+'DCF Valuation'!D8/(1+0.1)^3+'DCF Valuation'!E8/(1+0.1)^4+'DCF Valuation'!F8/(1+0.1)^5+'DCF Valuation'!F8*(1+0.02)/(MAX(0.1-0.02,0.0001))/(1+0.1)^5)/'DCF Valuation'!B27 | E4: =('DCF Valuation'!B8/(1+0.11)^1+'DCF Valuation'!C8/(1+0.11)^2+'DCF Valuation'!D8/(1+0.11)^3+'DCF Valuation'!E8/(1+0.11)^4+'DCF Valuation'!F8/(1+0.11)^5+'DCF Valuation'!F8*(1+0.02)/(MAX(0.11-0.02,0.0001))/(1+0.11)^5)/'DCF Valuation'!B27 | F4: =('DCF Valuation'!B8/(1+0.12)^1+'DCF Valuation'!C8/(1+0.12)^2+'DCF Valuation'!D8/(1+0.12)^3+'DCF Valuation'!E8/(1+0.12)^4+'DCF Valuation'!F8/(1+0.12)^5+'DCF Valuation'!F8*(1+0.02)/(MAX(0.12-0.02,0.0001))/(1+0.12)^5)/'DCF Valuation'!B27 | G4: =('DCF Valuation'!B8/(1+0.13)^1+'DCF Valuation'!C8/(1+0.13)^2+'DCF Valuation'!D8/(1+0.13)^3+'DCF Valuation'!E8/(1+0.13)^4+'DCF Valuation'!F8/(1+0.13)^5+'DCF Valuation'!F8*(1+0.02)/(MAX(0.13-0.02,0.0001))/(1+0.13)^5)/'DCF Valuation'!B27 | H4: =('DCF Valuation'!B8/(1+0.14)^1+'DCF Valuation'!C8/(1+0.14)^2+'DCF Valuation'!D8/(1+0.14)^3+'DCF Valuation'!E8/(1+0.14)^4+'DCF Valuation'!F8/(1+0.14)^5+'DCF Valuation'!F8*(1+0.02)/(MAX(0.14-0.02,0.0001))/(1+0.14)^5)/'DCF Valuation'!B27
A5: 0.025 | B5: =('DCF Valuation'!B8/(1+0.08)^1+'DCF Valuation'!C8/(1+0.08)^2+'DCF Valuation'!D8/(1+0.08)^3+'DCF Valuation'!E8/(1+0.08)^4+'DCF Valuation'!F8/(1+0.08)^5+'DCF Valuation'!F8*(1+0.025)/(MAX(0.08-0.025,0.0001))/(1+0.08)^5)/'DCF Valuation'!B27 | C5: =('DCF Valuation'!B8/(1+0.09)^1+'DCF Valuation'!C8/(1+0.09)^2+'DCF Valuation'!D8/(1+0.09)^3+'DCF Valuation'!E8/(1+0.09)^4+'DCF Valuation'!F8/(1+0.09)^5+'DCF Valuation'!F8*(1+0.025)/(MAX(0.09-0.025,0.0001))/(1+0.09)^5)/'DCF Valuation'!B27 | D5: =('DCF Valuation'!B8/(1+0.1)^1+'DCF Valuation'!C8/(1+0.1)^2+'DCF Valuation'!D8/(1+0.1)^3+'DCF Valuation'!E8/(1+0.1)^4+'DCF Valuation'!F8/(1+0.1)^5+'DCF Valuation'!F8*(1+0.025)/(MAX(0.1-0.025,0.0001))/(1+0.1)^5)/'DCF Valuation'!B27 | E5: =('DCF Valuation'!B8/(1+0.11)^1+'DCF Valuation'!C8/(1+0.11)^2+'DCF Valuation'!D8/(1+0.11)^3+'DCF Valuation'!E8/(1+0.11)^4+'DCF Valuation'!F8/(1+0.11)^5+'DCF Valuation'!F8*(1+0.025)/(MAX(0.11-0.025,0.0001))/(1+0.11)^5)/'DCF Valuation'!B27 | F5: =('DCF Valuation'!B8/(1+0.12)^1+'DCF Valuation'!C8/(1+0.12)^2+'DCF Valuation'!D8/(1+0.12)^3+'DCF Valuation'!E8/(1+0.12)^4+'DCF Valuation'!F8/(1+0.12)^5+'DCF Valuation'!F8*(1+0.025)/(MAX(0.12-0.025,0.0001))/(1+0.12)^5)/'DCF Valuation'!B27 | G5: =('DCF Valuation'!B8/(1+0.13)^1+'DCF Valuation'!C8/(1+0.13)^2+'DCF Valuation'!D8/(1+0.13)^3+'DCF Valuation'!E8/(1+0.13)^4+'DCF Valuation'!F8/(1+0.13)^5+'DCF Valuation'!F8*(1+0.025)/(MAX(0.13-0.025,0.0001))/(1+0.13)^5)/'DCF Valuation'!B27 | H5: =('DCF Valuation'!B8/(1+0.14)^1+'DCF Valuation'!C8/(1+0.14)^2+'DCF Valuation'!D8/(1+0.14)^3+'DCF Valuation'!E8/(1+0.14)^4+'DCF Valuation'!F8/(1+0.14)^5+'DCF Valuation'!F8*(1+0.025)/(MAX(0.14-0.025,0.0001))/(1+0.14)^5)/'DCF Valuation'!B27
A6: 0.03 | B6: =('DCF Valuation'!B8/(1+0.08)^1+'DCF Valuation'!C8/(1+0.08)^2+'DCF Valuation'!D8/(1+0.08)^3+'DCF Valuation'!E8/(1+0.08)^4+'DCF Valuation'!F8/(1+0.08)^5+'DCF Valuation'!F8*(1+0.03)/(MAX(0.08-0.03,0.0001))/(1+0.08)^5)/'DCF Valuation'!B27 | C6: =('DCF Valuation'!B8/(1+0.09)^1+'DCF Valuation'!C8/(1+0.09)^2+'DCF Valuation'!D8/(1+0.09)^3+'DCF Valuation'!E8/(1+0.09)^4+'DCF Valuation'!F8/(1+0.09)^5+'DCF Valuation'!F8*(1+0.03)/(MAX(0.09-0.03,0.0001))/(1+0.09)^5)/'DCF Valuation'!B27 | D6: =('DCF Valuation'!B8/(1+0.1)^1+'DCF Valuation'!C8/(1+0.1)^2+'DCF Valuation'!D8/(1+0.1)^3+'DCF Valuation'!E8/(1+0.1)^4+'DCF Valuation'!F8/(1+0.1)^5+'DCF Valuation'!F8*(1+0.03)/(MAX(0.1-0.03,0.0001))/(1+0.1)^5)/'DCF Valuation'!B27 | E6: =('DCF Valuation'!B8/(1+0.11)^1+'DCF Valuation'!C8/(1+0.11)^2+'DCF Valuation'!D8/(1+0.11)^3+'DCF Valuation'!E8/(1+0.11)^4+'DCF Valuation'!F8/(1+0.11)^5+'DCF Valuation'!F8*(1+0.03)/(MAX(0.11-0.03,0.0001))/(1+0.11)^5)/'DCF Valuation'!B27 | F6: =('DCF Valuation'!B8/(1+0.12)^1+'DCF Valuation'!C8/(1+0.12)^2+'DCF Valuation'!D8/(1+0.12)^3+'DCF Valuation'!E8/(1+0.12)^4+'DCF Valuation'!F8/(1+0.12)^5+'DCF Valuation'!F8*(1+0.03)/(MAX(0.12-0.03,0.0001))/(1+0.12)^5)/'DCF Valuation'!B27 | G6: =('DCF Valuation'!B8/(1+0.13)^1+'DCF Valuation'!C8/(1+0.13)^2+'DCF Valuation'!D8/(1+0.13)^3+'DCF Valuation'!E8/(1+0.13)^4+'DCF Valuation'!F8/(1+0.13)^5+'DCF Valuation'!F8*(1+0.03)/(MAX(0.13-0.03,0.0001))/(1+0.13)^5)/'DCF Valuation'!B27 | H6: =('DCF Valuation'!B8/(1+0.14)^1+'DCF Valuation'!C8/(1+0.14)^2+'DCF Valuation'!D8/(1+0.14)^3+'DCF Valuation'!E8/(1+0.14)^4+'DCF Valuation'!F8/(1+0.14)^5+'DCF Valuation'!F8*(1+0.03)/(MAX(0.14-0.03,0.0001))/(1+0.14)^5)/'DCF Valuation'!B27
A7: 0.035 | B7: =('DCF Valuation'!B8/(1+0.08)^1+'DCF Valuation'!C8/(1+0.08)^2+'DCF Valuation'!D8/(1+0.08)^3+'DCF Valuation'!E8/(1+0.08)^4+'DCF Valuation'!F8/(1+0.08)^5+'DCF Valuation'!F8*(1+0.035)/(MAX(0.08-0.035,0.0001))/(1+0.08)^5)/'DCF Valuation'!B27 | C7: =('DCF Valuation'!B8/(1+0.09)^1+'DCF Valuation'!C8/(1+0.09)^2+'DCF Valuation'!D8/(1+0.09)^3+'DCF Valuation'!E8/(1+0.09)^4+'DCF Valuation'!F8/(1+0.09)^5+'DCF Valuation'!F8*(1+0.035)/(MAX(0.09-0.035,0.0001))/(1+0.09)^5)/'DCF Valuation'!B27 | D7: =('DCF Valuation'!B8/(1+0.1)^1+'DCF Valuation'!C8/(1+0.1)^2+'DCF Valuation'!D8/(1+0.1)^3+'DCF Valuation'!E8/(1+0.1)^4+'DCF Valuation'!F8/(1+0.1)^5+'DCF Valuation'!F8*(1+0.035)/(MAX(0.1-0.035,0.0001))/(1+0.1)^5)/'DCF Valuation'!B27 | E7: =('DCF Valuation'!B8/(1+0.11)^1+'DCF Valuation'!C8/(1+0.11)^2+'DCF Valuation'!D8/(1+0.11)^3+'DCF Valuation'!E8/(1+0.11)^4+'DCF Valuation'!F8/(1+0.11)^5+'DCF Valuation'!F8*(1+0.035)/(MAX(0.11-0.035,0.0001))/(1+0.11)^5)/'DCF Valuation'!B27 | F7: =('DCF Valuation'!B8/(1+0.12)^1+'DCF Valuation'!C8/(1+0.12)^2+'DCF Valuation'!D8/(1+0.12)^3+'DCF Valuation'!E8/(1+0.12)^4+'DCF Valuation'!F8/(1+0.12)^5+'DCF Valuation'!F8*(1+0.035)/(MAX(0.12-0.035,0.0001))/(1+0.12)^5)/'DCF Valuation'!B27 | G7: =('DCF Valuation'!B8/(1+0.13)^1+'DCF Valuation'!C8/(1+0.13)^2+'DCF Valuation'!D8/(1+0.13)^3+'DCF Valuation'!E8/(1+0.13)^4+'DCF Valuation'!F8/(1+0.13)^5+'DCF Valuation'!F8*(1+0.035)/(MAX(0.13-0.035,0.0001))/(1+0.13)^5)/'DCF Valuation'!B27 | H7: =('DCF Valuation'!B8/(1+0.14)^1+'DCF Valuation'!C8/(1+0.14)^2+'DCF Valuation'!D8/(1+0.14)^3+'DCF Valuation'!E8/(1+0.14)^4+'DCF Valuation'!F8/(1+0.14)^5+'DCF Valuation'!F8*(1+0.035)/(MAX(0.14-0.035,0.0001))/(1+0.14)^5)/'DCF Valuation'!B27
A8: 0.04 | B8: =('DCF Valuation'!B8/(1+0.08)^1+'DCF Valuation'!C8/(1+0.08)^2+'DCF Valuation'!D8/(1+0.08)^3+'DCF Valuation'!E8/(1+0.08)^4+'DCF Valuation'!F8/(1+0.08)^5+'DCF Valuation'!F8*(1+0.04)/(MAX(0.08-0.04,0.0001))/(1+0.08)^5)/'DCF Valuation'!B27 | C8: =('DCF Valuation'!B8/(1+0.09)^1+'DCF Valuation'!C8/(1+0.09)^2+'DCF Valuation'!D8/(1+0.09)^3+'DCF Valuation'!E8/(1+0.09)^4+'DCF Valuation'!F8/(1+0.09)^5+'DCF Valuation'!F8*(1+0.04)/(MAX(0.09-0.04,0.0001))/(1+0.09)^5)/'DCF Valuation'!B27 | D8: =('DCF Valuation'!B8/(1+0.1)^1+'DCF Valuation'!C8/(1+0.1)^2+'DCF Valuation'!D8/(1+0.1)^3+'DCF Valuation'!E8/(1+0.1)^4+'DCF Valuation'!F8/(1+0.1)^5+'DCF Valuation'!F8*(1+0.04)/(MAX(0.1-0.04,0.0001))/(1+0.1)^5)/'DCF Valuation'!B27 | E8: =('DCF Valuation'!B8/(1+0.11)^1+'DCF Valuation'!C8/(1+0.11)^2+'DCF Valuation'!D8/(1+0.11)^3+'DCF Valuation'!E8/(1+0.11)^4+'DCF Valuation'!F8/(1+0.11)^5+'DCF Valuation'!F8*(1+0.04)/(MAX(0.11-0.04,0.0001))/(1+0.11)^5)/'DCF Valuation'!B27 | F8: =('DCF Valuation'!B8/(1+0.12)^1+'DCF Valuation'!C8/(1+0.12)^2+'DCF Valuation'!D8/(1+0.12)^3+'DCF Valuation'!E8/(1+0.12)^4+'DCF Valuation'!F8/(1+0.12)^5+'DCF Valuation'!F8*(1+0.04)/(MAX(0.12-0.04,0.0001))/(1+0.12)^5)/'DCF Valuation'!B27 | G8: =('DCF Valuation'!B8/(1+0.13)^1+'DCF Valuation'!C8/(1+0.13)^2+'DCF Valuation'!D8/(1+0.13)^3+'DCF Valuation'!E8/(1+0.13)^4+'DCF Valuation'!F8/(1+0.13)^5+'DCF Valuation'!F8*(1+0.04)/(MAX(0.13-0.04,0.0001))/(1+0.13)^5)/'DCF Valuation'!B27 | H8: =('DCF Valuation'!B8/(1+0.14)^1+'DCF Valuation'!C8/(1+0.14)^2+'DCF Valuation'!D8/(1+0.14)^3+'DCF Valuation'!E8/(1+0.14)^4+'DCF Valuation'!F8/(1+0.14)^5+'DCF Valuation'!F8*(1+0.04)/(MAX(0.14-0.04,0.0001))/(1+0.14)^5)/'DCF Valuation'!B27
A9: 0.045 | B9: =('DCF Valuation'!B8/(1+0.08)^1+'DCF Valuation'!C8/(1+0.08)^2+'DCF Valuation'!D8/(1+0.08)^3+'DCF Valuation'!E8/(1+0.08)^4+'DCF Valuation'!F8/(1+0.08)^5+'DCF Valuation'!F8*(1+0.045)/(MAX(0.08-0.045,0.0001))/(1+0.08)^5)/'DCF Valuation'!B27 | C9: =('DCF Valuation'!B8/(1+0.09)^1+'DCF Valuation'!C8/(1+0.09)^2+'DCF Valuation'!D8/(1+0.09)^3+'DCF Valuation'!E8/(1+0.09)^4+'DCF Valuation'!F8/(1+0.09)^5+'DCF Valuation'!F8*(1+0.045)/(MAX(0.09-0.045,0.0001))/(1+0.09)^5)/'DCF Valuation'!B27 | D9: =('DCF Valuation'!B8/(1+0.1)^1+'DCF Valuation'!C8/(1+0.1)^2+'DCF Valuation'!D8/(1+0.1)^3+'DCF Valuation'!E8/(1+0.1)^4+'DCF Valuation'!F8/(1+0.1)^5+'DCF Valuation'!F8*(1+0.045)/(MAX(0.1-0.045,0.0001))/(1+0.1)^5)/'DCF Valuation'!B27 | E9: =('DCF Valuation'!B8/(1+0.11)^1+'DCF Valuation'!C8/(1+0.11)^2+'DCF Valuation'!D8/(1+0.11)^3+'DCF Valuation'!E8/(1+0.11)^4+'DCF Valuation'!F8/(1+0.11)^5+'DCF Valuation'!F8*(1+0.045)/(MAX(0.11-0.045,0.0001))/(1+0.11)^5)/'DCF Valuation'!B27 | F9: =('DCF Valuation'!B8/(1+0.12)^1+'DCF Valuation'!C8/(1+0.12)^2+'DCF Valuation'!D8/(1+0.12)^3+'DCF Valuation'!E8/(1+0.12)^4+'DCF Valuation'!F8/(1+0.12)^5+'DCF Valuation'!F8*(1+0.045)/(MAX(0.12-0.045,0.0001))/(1+0.12)^5)/'DCF Valuation'!B27 | G9: =('DCF Valuation'!B8/(1+0.13)^1+'DCF Valuation'!C8/(1+0.13)^2+'DCF Valuation'!D8/(1+0.13)^3+'DCF Valuation'!E8/(1+0.13)^4+'DCF Valuation'!F8/(1+0.13)^5+'DCF Valuation'!F8*(1+0.045)/(MAX(0.13-0.045,0.0001))/(1+0.13)^5)/'DCF Valuation'!B27 | H9: =('DCF Valuation'!B8/(1+0.14)^1+'DCF Valuation'!C8/(1+0.14)^2+'DCF Valuation'!D8/(1+0.14)^3+'DCF Valuation'!E8/(1+0.14)^4+'DCF Valuation'!F8/(1+0.14)^5+'DCF Valuation'!F8*(1+0.045)/(MAX(0.14-0.045,0.0001))/(1+0.14)^5)/'DCF Valuation'!B27
A10: 0.05 | B10: =('DCF Valuation'!B8/(1+0.08)^1+'DCF Valuation'!C8/(1+0.08)^2+'DCF Valuation'!D8/(1+0.08)^3+'DCF Valuation'!E8/(1+0.08)^4+'DCF Valuation'!F8/(1+0.08)^5+'DCF Valuation'!F8*(1+0.05)/(MAX(0.08-0.05,0.0001))/(1+0.08)^5)/'DCF Valuation'!B27 | C10: =('DCF Valuation'!B8/(1+0.09)^1+'DCF Valuation'!C8/(1+0.09)^2+'DCF Valuation'!D8/(1+0.09)^3+'DCF Valuation'!E8/(1+0.09)^4+'DCF Valuation'!F8/(1+0.09)^5+'DCF Valuation'!F8*(1+0.05)/(MAX(0.09-0.05,0.0001))/(1+0.09)^5)/'DCF Valuation'!B27 | D10: =('DCF Valuation'!B8/(1+0.1)^1+'DCF Valuation'!C8/(1+0.1)^2+'DCF Valuation'!D8/(1+0.1)^3+'DCF Valuation'!E8/(1+0.1)^4+'DCF Valuation'!F8/(1+0.1)^5+'DCF Valuation'!F8*(1+0.05)/(MAX(0.1-0.05,0.0001))/(1+0.1)^5)/'DCF Valuation'!B27 | E10: =('DCF Valuation'!B8/(1+0.11)^1+'DCF Valuation'!C8/(1+0.11)^2+'DCF Valuation'!D8/(1+0.11)^3+'DCF Valuation'!E8/(1+0.11)^4+'DCF Valuation'!F8/(1+0.11)^5+'DCF Valuation'!F8*(1+0.05)/(MAX(0.11-0.05,0.0001))/(1+0.11)^5)/'DCF Valuation'!B27 | F10: =('DCF Valuation'!B8/(1+0.12)^1+'DCF Valuation'!C8/(1+0.12)^2+'DCF Valuation'!D8/(1+0.12)^3+'DCF Valuation'!E8/(1+0.12)^4+'DCF Valuation'!F8/(1+0.12)^5+'DCF Valuation'!F8*(1+0.05)/(MAX(0.12-0.05,0.0001))/(1+0.12)^5)/'DCF Valuation'!B27 | G10: =('DCF Valuation'!B8/(1+0.13)^1+'DCF Valuation'!C8/(1+0.13)^2+'DCF Valuation'!D8/(1+0.13)^3+'DCF Valuation'!E8/(1+0.13)^4+'DCF Valuation'!F8/(1+0.13)^5+'DCF Valuation'!F8*(1+0.05)/(MAX(0.13-0.05,0.0001))/(1+0.13)^5)/'DCF Valuation'!B27 | H10: =('DCF Valuation'!B8/(1+0.14)^1+'DCF Valuation'!C8/(1+0.14)^2+'DCF Valuation'!D8/(1+0.14)^3+'DCF Valuation'!E8/(1+0.14)^4+'DCF Valuation'!F8/(1+0.14)^5+'DCF Valuation'!F8*(1+0.05)/(MAX(0.14-0.05,0.0001))/(1+0.14)^5)/'DCF Valuation'!B27
A12: LEGEND
A13: Red Header | B13: Current WACC (10%) or TGR (3%) axis
A14: Yellow Cell | B14: Base Case (WACC 10%, TGR 3%)
A15: Peach Cell | B15: Single dimension match

Sheet Dashboard
B1: IDBI BANK – INVESTMENT ANALYSIS DASHBOARD
B3: STOCK SNAPSHOT (April 2026)
B4: Current Market Price | D4: Market Cap (₹ Cr) | F4: P/E Ratio | H4: P/B Ratio
B5: =Inputs!B7 | D5: =Inputs!B8 | F5: =Inputs!B12 | H5: =Inputs!B13
B6: EPS – ₹ | D6: Book Value / Share – ₹
B7: =Inputs!B14 | D7: =Inputs!B15
B10: VALUATION SUMMARY
B11: Valuation Method | C11: Implied Price (₹) | D11: CMP (₹) | E11: Upside / Downside %
B12: DCF Valuation | C12: ='DCF Valuation'!B28 | D12: =Inputs!B7 | E12: =IF(D12=0,0,(C12-D12)/D12)
B13: Comps – EV/EBITDA | C13: ='Trading Comps'!E15 | D13: =Inputs!B7 | E13: =IF(D13=0,0,(C13-D13)/D13)
B14: Comps – EV/Revenue | C14: ='Trading Comps'!E16 | D14: =Inputs!B7 | E14: =IF(D14=0,0,(C14-D14)/D14)
B15: Comps – P/E | C15: ='Trading Comps'!E17 | D15: =Inputs!B7 | E15: =IF(D15=0,0,(C15-D15)/D15)
B16: Comps – P/B | C16: ='Trading Comps'!E18 | D16: =Inputs!B7 | E16: =IF(D16=0,0,(C16-D16)/D16)
B17: Scenario – Base Case | C17: ='Scenario Analysis'!B27 | D17: =Inputs!B7 | E17: =IF(D17=0,0,(C17-D17)/D17)
B18: Scenario – Bull Case | C18: ='Scenario Analysis'!C27 | D18: =Inputs!B7 | E18: =IF(D18=0,0,(C18-D18)/D18)
B19: Scenario – Bear Case | C19: ='Scenario Analysis'!D27 | D19: =Inputs!B7 | E19: =IF(D19=0,0,(C19-D19)/D19)
B21: KEY FINANCIAL METRICS (FY 2024-25 Actuals)
B22: Interest Income (₹ Mn) | D22: NII (₹ Mn) | F22: NPAT (₹ Mn) | H22: Total Assets (₹ Cr)
B23: ='3-Statements Model'!B4 | D23: ='3-Statements Model'!B8 | F23: ='3-Statements Model'!B13 | H23: ='3-Statements Model'!B27
B24: Advances (₹ Cr) | D24: Deposits (₹ Cr) | F24: ROE % | H24: ROA %
B25: ='3-Statements Model'!B23 | D25: ='3-Statements Model'!B29 | F25: =Inputs!B45 | H25: =Inputs!B46
B26: NIM % | D26: Gross NPA % | F26: Net NPA % | H26: CAR %
B27: =Inputs!B47 | D27: =Inputs!B49 | F27: =Inputs!B50 | H27: =Inputs!B51
B30: 5-YEAR PROJECTIONS SUMMARY (₹ Millions)
B31: Metric | C31: FY 2024-25 | D31: FY 2025-26 | E31: FY 2026-27 | F31: FY 2027-28 | G31: FY 2028-29
B32: Interest Income | C32: ='3-Statements Model'!B4 | D32: ='3-Statements Model'!C4 | E32: ='3-Statements Model'!D4 | F32: ='3-Statements Model'!E4 | G32: ='3-Statements Model'!F4
B33: NII | C33: ='3-Statements Model'!B8 | D33: ='3-Statements Model'!C8 | E33: ='3-Statements Model'!D8 | F33: ='3-Statements Model'!E8 | G33: ='3-Statements Model'!F8
B34: NPAT | C34: ='3-Statements Model'!B13 | D34: ='3-Statements Model'!C13 | E34: ='3-Statements Model'!D13 | F34: ='3-Statements Model'!E13 | G34: ='3-Statements Model'!F13
B37: MODEL NOTES
B38: 1. P&L figures in ₹ Millions; Balance Sheet in ₹ Crore. Conversion: ÷10 for Cr→Mn used where needed.
B39: 2. Blue font = hardcoded inputs (Inputs sheet only). Black font = formulas in all other cells.
B40: 3. Scenario selector (Inputs!B) drives all P&L, Cash Flow, and Valuation outputs dynamically.
B41: 4. DCF uses WACC ≈ 10% (Rf 6.5% + β 0.85 × ERP 7%) and terminal growth rate 3%.
B42: 5. Sensitivity Analysis tests WACC 8%–14% vs Terminal Growth 2%–5% in 2-way table.
B43: 6. Trading Comps based on peer bank data entered in Inputs sheet (April 2026 market data).
